<?xml version="1.0"?>

<robot name= "my_robot">

    <link name="base_link">
        <visual>
            <origin xyz="0 0 0" rpy="0 0 0"/>
            <geometry>
                <cylinder radius="0.1" length="0.2"/>
            </geometry>

            <material name="white">>
                <color rgba="1 1 1 1"/>
            </material>
        </visual>

        <collision>
            <origin xyz="0 0 0" rpy="0 0 0"/>
            <geometry>
                <cylinder radius="0.1" length="0.2"/>
            </geometry>
        </collision>

        <inertial>
            <mass value="0.5" />
            <inertia ixx="1.0" ixy="0.0" ixz="0.0" iyy="1.0" iyz="0.0" izz="1.0" />
        </inertial>
       
    </link>

    <gazebo reference="base_link">
        <material>Gazebo/Orange</material>
    </gazebo>


    <link name="link_1">

        <visual>
            <origin xyz="0 0 0" rpy="0 0 0"/>
            <geometry>
                 <box size="0.6 0.1 0.2"/>
            </geometry>

            <!--material>
                <color rgba="1 1 1 1"/>
            </material-->
        </visual>

        <collision>
            <origin xyz="0 0 0" rpy="0 0 0"/>
            <geometry>
                 <box size="0.6 0.1 0.2"/>
            </geometry>

            <!--material>
                <color rgba="1 1 1 1"/>
            </material-->
        </collision>

        <inertial>
            <mass value="0.5" />
            <inertia ixx="1.0" ixy="0.0" ixz="0.0" iyy="1.0" iyz="0.0" izz="1.0" />
        </inertial>
    </link>

    <gazebo reference="link_1">
        <sensor type="camera" name="camera1">
            <plugin name="camera_controller" filename="libgazebo_ros_camera.so">
            </plugin>
        </sensor>
    </gazebo>


    <joint name="joint_1" type="continuous">

        <parent link="base_link"/>
        <child link="link_1"/>
        <axis rpy="0 0 0" xyz="0 0 1"/>
    </joint>

</robot>